{"event":"stderr","body":"node:internal/modules/cjs/loader:1228\n  throw err;\n  ^\n\nError: Cannot find module '/home/user/funmula/dive-mcp-py/echo.js'\n    at Function._resolveFilename (node:internal/modules/cjs/loader:1225:15)\n    at Function._load (node:internal/modules/cjs/loader:1055:27)\n    at TracingChannel.traceSync (node:diagnostics_channel:322:14)\n    at wrapModuleLoad (node:internal/modules/cjs/loader:220:24)\n    at Function.executeUserEntryPoint [as runMain] (node:internal/modules/run_main:170:5)\n    at node:internal/main/run_main_module:36:49 {\n  code: 'MODULE_NOT_FOUND',\n  requireStack: []\n}\n\nNode.js v22.14.0\n","mcp_server_name":"echo","client_state":"init","timestamp":"2025-05-08T02:37:22.341999Z"}
{"event":"session_error","body":"  | dive_mcp_host.host.errors.McpSessionGroupError: ProcessLookupError for echo: (ProcessLookupError(),) (1 sub-exception)\n  +-+---------------- 1 ----------------\n    | Exception Group Traceback (most recent call last):\n    |   File \"/home/user/funmula/dive-mcp-py/dive_mcp_host/host/tools/stdio_server.py\", line 149, in stdio_client\n    |     yield read_stream, write_stream\n    |   File \"/home/user/funmula/dive-mcp-py/dive_mcp_host/host/tools/mcp_server.py\", line 172, in _client_watcher\n    |     ClientSession(*streams) as session,\n    |     ^^^^^^^^^^^^^^^^^^^^^^^\n    |   File \"/home/user/funmula/dive-mcp-py/.venv/lib/python3.12/site-packages/mcp/shared/session.py\", line 210, in __aexit__\n    |     return await self._task_group.__aexit__(exc_type, exc_val, exc_tb)\n    |            ^^^^^^^^^^^^^^^^^^^^^^^^^^^^^^^^^^^^^^^^^^^^^^^^^^^^^^^^^^^\n    |   File \"/home/user/funmula/dive-mcp-py/.venv/lib/python3.12/site-packages/anyio/_backends/_asyncio.py\", line 772, in __aexit__\n    |     raise BaseExceptionGroup(\n    | ExceptionGroup: unhandled errors in a TaskGroup (1 sub-exception)\n    +-+---------------- 1 ----------------\n      | Traceback (most recent call last):\n      |   File \"/home/user/funmula/dive-mcp-py/.venv/lib/python3.12/site-packages/anyio/streams/memory.py\", line 111, in receive\n      |     return self.receive_nowait()\n      |            ^^^^^^^^^^^^^^^^^^^^^\n      |   File \"/home/user/funmula/dive-mcp-py/.venv/lib/python3.12/site-packages/anyio/streams/memory.py\", line 106, in receive_nowait\n      |     raise WouldBlock\n      | anyio.WouldBlock\n      | \n      | During handling of the above exception, another exception occurred:\n      | \n      | Traceback (most recent call last):\n      |   File \"/home/user/funmula/dive-mcp-py/dive_mcp_host/host/tools/mcp_server.py\", line 176, in _client_watcher\n      |     self._initialize_result = await session.initialize()\n      |                               ^^^^^^^^^^^^^^^^^^^^^^^^^^\n      |   File \"/home/user/funmula/dive-mcp-py/.venv/lib/python3.12/site-packages/mcp/client/session.py\", line 122, in initialize\n      |     result = await self.send_request(\n      |              ^^^^^^^^^^^^^^^^^^^^^^^^\n      |   File \"/home/user/funmula/dive-mcp-py/.venv/lib/python3.12/site-packages/mcp/shared/session.py\", line 252, in send_request\n      |     response_or_error = await response_stream_reader.receive()\n      |                         ^^^^^^^^^^^^^^^^^^^^^^^^^^^^^^^^^^^^^^\n      |   File \"/home/user/funmula/dive-mcp-py/.venv/lib/python3.12/site-packages/anyio/streams/memory.py\", line 119, in receive\n      |     await receive_event.wait()\n      |   File \"/home/user/funmula/dive-mcp-py/.venv/lib/python3.12/site-packages/anyio/_backends/_asyncio.py\", line 1774, in wait\n      |     await self._event.wait()\n      |   File \"/home/user/.local/share/uv/python/cpython-3.12.9-linux-x86_64-gnu/lib/python3.12/asyncio/locks.py\", line 212, in wait\n      |     await fut\n      | asyncio.exceptions.CancelledError\n      | \n      | The above exception was the direct cause of the following exception:\n      | \n      | Traceback (most recent call last):\n      |   File \"/home/user/funmula/dive-mcp-py/dive_mcp_host/host/tools/mcp_server.py\", line 174, in _client_watcher\n      |     async with asyncio.timeout(10):\n      |                ^^^^^^^^^^^^^^^^^^^\n      |   File \"/home/user/.local/share/uv/python/cpython-3.12.9-linux-x86_64-gnu/lib/python3.12/asyncio/timeouts.py\", line 115, in __aexit__\n      |     raise TimeoutError from exc_val\n      | TimeoutError\n      +------------------------------------\n    | \n    | During handling of the above exception, another exception occurred:\n    | \n    | Traceback (most recent call last):\n    |   File \"/home/user/funmula/dive-mcp-py/dive_mcp_host/host/tools/stdio_server.py\", line 156, in stdio_client\n    |     await terminate_windows_process(process)\n    |   File \"/home/user/funmula/dive-mcp-py/.venv/lib/python3.12/site-packages/mcp/client/stdio/win32.py\", line 104, in terminate_windows_process\n    |     process.terminate()\n    |   File \"/home/user/funmula/dive-mcp-py/.venv/lib/python3.12/site-packages/anyio/_backends/_asyncio.py\", line 1085, in terminate\n    |     self._process.terminate()\n    |   File \"/home/user/.local/share/uv/python/cpython-3.12.9-linux-x86_64-gnu/lib/python3.12/asyncio/subprocess.py\", line 143, in terminate\n    |     self._transport.terminate()\n    |   File \"/home/user/.local/share/uv/python/cpython-3.12.9-linux-x86_64-gnu/lib/python3.12/asyncio/base_subprocess.py\", line 149, in terminate\n    |     self._check_proc()\n    |   File \"/home/user/.local/share/uv/python/cpython-3.12.9-linux-x86_64-gnu/lib/python3.12/asyncio/base_subprocess.py\", line 142, in _check_proc\n    |     raise ProcessLookupError()\n    | ProcessLookupError\n","mcp_server_name":"echo","client_state":"init","timestamp":"2025-05-08T02:37:32.284574Z"}
{"event":"status_change","body":"client status changed, echo failed, error: False","mcp_server_name":"echo","client_state":"failed","timestamp":"2025-05-08T02:37:32.284898Z"}
{"event":"stderr","body":"node:internal/modules/cjs/loader:1228\n  throw err;\n  ^\n\nError: Cannot find module '/home/user/funmula/dive-mcp-py/echo.js'\n    at Function._resolveFilename (node:internal/modules/cjs/loader:1225:15)\n    at Function._load (node:internal/modules/cjs/loader:1055:27)\n    at TracingChannel.traceSync (node:diagnostics_channel:322:14)\n    at wrapModuleLoad (node:internal/modules/cjs/loader:220:24)\n    at Function.executeUserEntryPoint [as runMain] (node:internal/modules/run_main:170:5)\n    at node:internal/main/run_main_module:36:49 {\n  code: 'MODULE_NOT_FOUND',\n  requireStack: []\n}\n\nNode.js v22.14.0\n","mcp_server_name":"echo","client_state":"init","timestamp":"2025-05-08T02:43:06.718086Z"}
{"event":"session_error","body":"  | dive_mcp_host.host.errors.McpSessionGroupError: ProcessLookupError for echo: (ProcessLookupError(),) (1 sub-exception)\n  +-+---------------- 1 ----------------\n    | Exception Group Traceback (most recent call last):\n    |   File \"/home/user/funmula/dive-mcp-py/dive_mcp_host/host/tools/stdio_server.py\", line 149, in stdio_client\n    |     yield read_stream, write_stream\n    |   File \"/home/user/funmula/dive-mcp-py/dive_mcp_host/host/tools/mcp_server.py\", line 172, in _client_watcher\n    |     ClientSession(*streams) as session,\n    |     ^^^^^^^^^^^^^^^^^^^^^^^\n    |   File \"/home/user/funmula/dive-mcp-py/.venv/lib/python3.12/site-packages/mcp/shared/session.py\", line 210, in __aexit__\n    |     return await self._task_group.__aexit__(exc_type, exc_val, exc_tb)\n    |            ^^^^^^^^^^^^^^^^^^^^^^^^^^^^^^^^^^^^^^^^^^^^^^^^^^^^^^^^^^^\n    |   File \"/home/user/funmula/dive-mcp-py/.venv/lib/python3.12/site-packages/anyio/_backends/_asyncio.py\", line 772, in __aexit__\n    |     raise BaseExceptionGroup(\n    | ExceptionGroup: unhandled errors in a TaskGroup (1 sub-exception)\n    +-+---------------- 1 ----------------\n      | Traceback (most recent call last):\n      |   File \"/home/user/funmula/dive-mcp-py/.venv/lib/python3.12/site-packages/anyio/streams/memory.py\", line 111, in receive\n      |     return self.receive_nowait()\n      |            ^^^^^^^^^^^^^^^^^^^^^\n      |   File \"/home/user/funmula/dive-mcp-py/.venv/lib/python3.12/site-packages/anyio/streams/memory.py\", line 106, in receive_nowait\n      |     raise WouldBlock\n      | anyio.WouldBlock\n      | \n      | During handling of the above exception, another exception occurred:\n      | \n      | Traceback (most recent call last):\n      |   File \"/home/user/funmula/dive-mcp-py/dive_mcp_host/host/tools/mcp_server.py\", line 176, in _client_watcher\n      |     self._initialize_result = await session.initialize()\n      |                               ^^^^^^^^^^^^^^^^^^^^^^^^^^\n      |   File \"/home/user/funmula/dive-mcp-py/.venv/lib/python3.12/site-packages/mcp/client/session.py\", line 122, in initialize\n      |     result = await self.send_request(\n      |              ^^^^^^^^^^^^^^^^^^^^^^^^\n      |   File \"/home/user/funmula/dive-mcp-py/.venv/lib/python3.12/site-packages/mcp/shared/session.py\", line 252, in send_request\n      |     response_or_error = await response_stream_reader.receive()\n      |                         ^^^^^^^^^^^^^^^^^^^^^^^^^^^^^^^^^^^^^^\n      |   File \"/home/user/funmula/dive-mcp-py/.venv/lib/python3.12/site-packages/anyio/streams/memory.py\", line 119, in receive\n      |     await receive_event.wait()\n      |   File \"/home/user/funmula/dive-mcp-py/.venv/lib/python3.12/site-packages/anyio/_backends/_asyncio.py\", line 1774, in wait\n      |     await self._event.wait()\n      |   File \"/home/user/.local/share/uv/python/cpython-3.12.9-linux-x86_64-gnu/lib/python3.12/asyncio/locks.py\", line 212, in wait\n      |     await fut\n      | asyncio.exceptions.CancelledError\n      | \n      | The above exception was the direct cause of the following exception:\n      | \n      | Traceback (most recent call last):\n      |   File \"/home/user/funmula/dive-mcp-py/dive_mcp_host/host/tools/mcp_server.py\", line 174, in _client_watcher\n      |     async with asyncio.timeout(10):\n      |                ^^^^^^^^^^^^^^^^^^^\n      |   File \"/home/user/.local/share/uv/python/cpython-3.12.9-linux-x86_64-gnu/lib/python3.12/asyncio/timeouts.py\", line 115, in __aexit__\n      |     raise TimeoutError from exc_val\n      | TimeoutError\n      +------------------------------------\n    | \n    | During handling of the above exception, another exception occurred:\n    | \n    | Traceback (most recent call last):\n    |   File \"/home/user/funmula/dive-mcp-py/dive_mcp_host/host/tools/stdio_server.py\", line 156, in stdio_client\n    |     await terminate_windows_process(process)\n    |   File \"/home/user/funmula/dive-mcp-py/.venv/lib/python3.12/site-packages/mcp/client/stdio/win32.py\", line 104, in terminate_windows_process\n    |     process.terminate()\n    |   File \"/home/user/funmula/dive-mcp-py/.venv/lib/python3.12/site-packages/anyio/_backends/_asyncio.py\", line 1085, in terminate\n    |     self._process.terminate()\n    |   File \"/home/user/.local/share/uv/python/cpython-3.12.9-linux-x86_64-gnu/lib/python3.12/asyncio/subprocess.py\", line 143, in terminate\n    |     self._transport.terminate()\n    |   File \"/home/user/.local/share/uv/python/cpython-3.12.9-linux-x86_64-gnu/lib/python3.12/asyncio/base_subprocess.py\", line 149, in terminate\n    |     self._check_proc()\n    |   File \"/home/user/.local/share/uv/python/cpython-3.12.9-linux-x86_64-gnu/lib/python3.12/asyncio/base_subprocess.py\", line 142, in _check_proc\n    |     raise ProcessLookupError()\n    | ProcessLookupError\n","mcp_server_name":"echo","client_state":"init","timestamp":"2025-05-08T02:43:16.705443Z"}
{"event":"status_change","body":"client status changed, echo failed, error: False","mcp_server_name":"echo","client_state":"failed","timestamp":"2025-05-08T02:43:16.705785Z"}
{"event":"session_error","body":"  | dive_mcp_host.host.errors.McpSessionGroupError: Client initialization error for echo: (TypeError(\"Header value must be str or bytes, not <class 'pydantic.types.SecretStr'>\"),) (1 sub-exception)\n  +-+---------------- 1 ----------------\n    | Traceback (most recent call last):\n    |   File \"/home/user/funmula/dive-mcp-py/.venv/lib/python3.12/site-packages/mcp/client/sse.py\", line 46, in sse_client\n    |     async with httpx.AsyncClient(headers=headers) as client:\n    |                ^^^^^^^^^^^^^^^^^^^^^^^^^^^^^^^^^^\n    |   File \"/home/user/funmula/dive-mcp-py/.venv/lib/python3.12/site-packages/httpx/_client.py\", line 1376, in __init__\n    |     super().__init__(\n    |   File \"/home/user/funmula/dive-mcp-py/.venv/lib/python3.12/site-packages/httpx/_client.py\", line 210, in __init__\n    |     self.headers = Headers(headers)\n    |                    ^^^^^^^^^^^^^^^^\n    |   File \"/home/user/funmula/dive-mcp-py/.venv/lib/python3.12/site-packages/httpx/_models.py\", line 156, in __init__\n    |     bytes_value = _normalize_header_value(v, encoding)\n    |                   ^^^^^^^^^^^^^^^^^^^^^^^^^^^^^^^^^^^^\n    |   File \"/home/user/funmula/dive-mcp-py/.venv/lib/python3.12/site-packages/httpx/_models.py\", line 81, in _normalize_header_value\n    |     raise TypeError(f\"Header value must be str or bytes, not {type(value)}\")\n    | TypeError: Header value must be str or bytes, not <class 'pydantic.types.SecretStr'>\n    +------------------------------------\n","mcp_server_name":"echo","client_state":"init","timestamp":"2025-05-08T02:57:54.930328Z"}
{"event":"session_error","body":"  | dive_mcp_host.host.errors.McpSessionGroupError: Client initialization error for echo: (TypeError(\"Header value must be str or bytes, not <class 'pydantic.types.SecretStr'>\"),) (1 sub-exception)\n  +-+---------------- 1 ----------------\n    | Traceback (most recent call last):\n    |   File \"/home/user/funmula/dive-mcp-py/.venv/lib/python3.12/site-packages/mcp/client/sse.py\", line 46, in sse_client\n    |     async with httpx.AsyncClient(headers=headers) as client:\n    |                ^^^^^^^^^^^^^^^^^^^^^^^^^^^^^^^^^^\n    |   File \"/home/user/funmula/dive-mcp-py/.venv/lib/python3.12/site-packages/httpx/_client.py\", line 1376, in __init__\n    |     super().__init__(\n    |   File \"/home/user/funmula/dive-mcp-py/.venv/lib/python3.12/site-packages/httpx/_client.py\", line 210, in __init__\n    |     self.headers = Headers(headers)\n    |                    ^^^^^^^^^^^^^^^^\n    |   File \"/home/user/funmula/dive-mcp-py/.venv/lib/python3.12/site-packages/httpx/_models.py\", line 156, in __init__\n    |     bytes_value = _normalize_header_value(v, encoding)\n    |                   ^^^^^^^^^^^^^^^^^^^^^^^^^^^^^^^^^^^^\n    |   File \"/home/user/funmula/dive-mcp-py/.venv/lib/python3.12/site-packages/httpx/_models.py\", line 81, in _normalize_header_value\n    |     raise TypeError(f\"Header value must be str or bytes, not {type(value)}\")\n    | TypeError: Header value must be str or bytes, not <class 'pydantic.types.SecretStr'>\n    +------------------------------------\n","mcp_server_name":"echo","client_state":"init","timestamp":"2025-05-08T02:57:57.938906Z"}
{"event":"session_error","body":"  | dive_mcp_host.host.errors.McpSessionGroupError: Client initialization error for echo: (TypeError(\"Header value must be str or bytes, not <class 'pydantic.types.SecretStr'>\"),) (1 sub-exception)\n  +-+---------------- 1 ----------------\n    | Traceback (most recent call last):\n    |   File \"/home/user/funmula/dive-mcp-py/.venv/lib/python3.12/site-packages/mcp/client/sse.py\", line 46, in sse_client\n    |     async with httpx.AsyncClient(headers=headers) as client:\n    |                ^^^^^^^^^^^^^^^^^^^^^^^^^^^^^^^^^^\n    |   File \"/home/user/funmula/dive-mcp-py/.venv/lib/python3.12/site-packages/httpx/_client.py\", line 1376, in __init__\n    |     super().__init__(\n    |   File \"/home/user/funmula/dive-mcp-py/.venv/lib/python3.12/site-packages/httpx/_client.py\", line 210, in __init__\n    |     self.headers = Headers(headers)\n    |                    ^^^^^^^^^^^^^^^^\n    |   File \"/home/user/funmula/dive-mcp-py/.venv/lib/python3.12/site-packages/httpx/_models.py\", line 156, in __init__\n    |     bytes_value = _normalize_header_value(v, encoding)\n    |                   ^^^^^^^^^^^^^^^^^^^^^^^^^^^^^^^^^^^^\n    |   File \"/home/user/funmula/dive-mcp-py/.venv/lib/python3.12/site-packages/httpx/_models.py\", line 81, in _normalize_header_value\n    |     raise TypeError(f\"Header value must be str or bytes, not {type(value)}\")\n    | TypeError: Header value must be str or bytes, not <class 'pydantic.types.SecretStr'>\n    +------------------------------------\n","mcp_server_name":"echo","client_state":"init","timestamp":"2025-05-08T02:58:00.947392Z"}
{"event":"status_change","body":"client status changed, echo failed, error: False","mcp_server_name":"echo","client_state":"failed","timestamp":"2025-05-08T02:58:00.948204Z"}
{"event":"session_error","body":"  | dive_mcp_host.host.errors.McpSessionGroupError: Client initialization error for echo: (TypeError(\"Header value must be str or bytes, not <class 'pydantic.types.SecretStr'>\"),) (1 sub-exception)\n  +-+---------------- 1 ----------------\n    | Traceback (most recent call last):\n    |   File \"/home/user/funmula/dive-mcp-py/.venv/lib/python3.12/site-packages/mcp/client/sse.py\", line 46, in sse_client\n    |     async with httpx.AsyncClient(headers=headers) as client:\n    |                ^^^^^^^^^^^^^^^^^^^^^^^^^^^^^^^^^^\n    |   File \"/home/user/funmula/dive-mcp-py/.venv/lib/python3.12/site-packages/httpx/_client.py\", line 1376, in __init__\n    |     super().__init__(\n    |   File \"/home/user/funmula/dive-mcp-py/.venv/lib/python3.12/site-packages/httpx/_client.py\", line 210, in __init__\n    |     self.headers = Headers(headers)\n    |                    ^^^^^^^^^^^^^^^^\n    |   File \"/home/user/funmula/dive-mcp-py/.venv/lib/python3.12/site-packages/httpx/_models.py\", line 156, in __init__\n    |     bytes_value = _normalize_header_value(v, encoding)\n    |                   ^^^^^^^^^^^^^^^^^^^^^^^^^^^^^^^^^^^^\n    |   File \"/home/user/funmula/dive-mcp-py/.venv/lib/python3.12/site-packages/httpx/_models.py\", line 81, in _normalize_header_value\n    |     raise TypeError(f\"Header value must be str or bytes, not {type(value)}\")\n    | TypeError: Header value must be str or bytes, not <class 'pydantic.types.SecretStr'>\n    +------------------------------------\n","mcp_server_name":"echo","client_state":"init","timestamp":"2025-05-08T02:58:21.841217Z"}
{"event":"session_error","body":"  | dive_mcp_host.host.errors.McpSessionGroupError: Client initialization error for echo: (TypeError(\"Header value must be str or bytes, not <class 'pydantic.types.SecretStr'>\"),) (1 sub-exception)\n  +-+---------------- 1 ----------------\n    | Traceback (most recent call last):\n    |   File \"/home/user/funmula/dive-mcp-py/.venv/lib/python3.12/site-packages/mcp/client/sse.py\", line 46, in sse_client\n    |     async with httpx.AsyncClient(headers=headers) as client:\n    |                ^^^^^^^^^^^^^^^^^^^^^^^^^^^^^^^^^^\n    |   File \"/home/user/funmula/dive-mcp-py/.venv/lib/python3.12/site-packages/httpx/_client.py\", line 1376, in __init__\n    |     super().__init__(\n    |   File \"/home/user/funmula/dive-mcp-py/.venv/lib/python3.12/site-packages/httpx/_client.py\", line 210, in __init__\n    |     self.headers = Headers(headers)\n    |                    ^^^^^^^^^^^^^^^^\n    |   File \"/home/user/funmula/dive-mcp-py/.venv/lib/python3.12/site-packages/httpx/_models.py\", line 156, in __init__\n    |     bytes_value = _normalize_header_value(v, encoding)\n    |                   ^^^^^^^^^^^^^^^^^^^^^^^^^^^^^^^^^^^^\n    |   File \"/home/user/funmula/dive-mcp-py/.venv/lib/python3.12/site-packages/httpx/_models.py\", line 81, in _normalize_header_value\n    |     raise TypeError(f\"Header value must be str or bytes, not {type(value)}\")\n    | TypeError: Header value must be str or bytes, not <class 'pydantic.types.SecretStr'>\n    +------------------------------------\n","mcp_server_name":"echo","client_state":"init","timestamp":"2025-05-08T02:58:24.848975Z"}
{"event":"session_error","body":"  | dive_mcp_host.host.errors.McpSessionGroupError: Client initialization error for echo: (TypeError(\"Header value must be str or bytes, not <class 'pydantic.types.SecretStr'>\"),) (1 sub-exception)\n  +-+---------------- 1 ----------------\n    | Traceback (most recent call last):\n    |   File \"/home/user/funmula/dive-mcp-py/.venv/lib/python3.12/site-packages/mcp/client/sse.py\", line 46, in sse_client\n    |     async with httpx.AsyncClient(headers=headers) as client:\n    |                ^^^^^^^^^^^^^^^^^^^^^^^^^^^^^^^^^^\n    |   File \"/home/user/funmula/dive-mcp-py/.venv/lib/python3.12/site-packages/httpx/_client.py\", line 1376, in __init__\n    |     super().__init__(\n    |   File \"/home/user/funmula/dive-mcp-py/.venv/lib/python3.12/site-packages/httpx/_client.py\", line 210, in __init__\n    |     self.headers = Headers(headers)\n    |                    ^^^^^^^^^^^^^^^^\n    |   File \"/home/user/funmula/dive-mcp-py/.venv/lib/python3.12/site-packages/httpx/_models.py\", line 156, in __init__\n    |     bytes_value = _normalize_header_value(v, encoding)\n    |                   ^^^^^^^^^^^^^^^^^^^^^^^^^^^^^^^^^^^^\n    |   File \"/home/user/funmula/dive-mcp-py/.venv/lib/python3.12/site-packages/httpx/_models.py\", line 81, in _normalize_header_value\n    |     raise TypeError(f\"Header value must be str or bytes, not {type(value)}\")\n    | TypeError: Header value must be str or bytes, not <class 'pydantic.types.SecretStr'>\n    +------------------------------------\n","mcp_server_name":"echo","client_state":"init","timestamp":"2025-05-08T02:58:27.857330Z"}
{"event":"status_change","body":"client status changed, echo failed, error: False","mcp_server_name":"echo","client_state":"failed","timestamp":"2025-05-08T02:58:27.858149Z"}
{"event":"session_error","body":"  | dive_mcp_host.host.errors.McpSessionGroupError: Client initialization error for echo: (ConnectError('All connection attempts failed'),) (1 sub-exception)\n  +-+---------------- 1 ----------------\n    | Traceback (most recent call last):\n    |   File \"/home/user/funmula/dive-mcp-py/.venv/lib/python3.12/site-packages/httpx/_transports/default.py\", line 101, in map_httpcore_exceptions\n    |     yield\n    |   File \"/home/user/funmula/dive-mcp-py/.venv/lib/python3.12/site-packages/httpx/_transports/default.py\", line 394, in handle_async_request\n    |     resp = await self._pool.handle_async_request(req)\n    |            ^^^^^^^^^^^^^^^^^^^^^^^^^^^^^^^^^^^^^^^^^^\n    |   File \"/home/user/funmula/dive-mcp-py/.venv/lib/python3.12/site-packages/httpcore/_async/connection_pool.py\", line 256, in handle_async_request\n    |     raise exc from None\n    |   File \"/home/user/funmula/dive-mcp-py/.venv/lib/python3.12/site-packages/httpcore/_async/connection_pool.py\", line 236, in handle_async_request\n    |     response = await connection.handle_async_request(\n    |                ^^^^^^^^^^^^^^^^^^^^^^^^^^^^^^^^^^^^^^\n    |   File \"/home/user/funmula/dive-mcp-py/.venv/lib/python3.12/site-packages/httpcore/_async/connection.py\", line 101, in handle_async_request\n    |     raise exc\n    |   File \"/home/user/funmula/dive-mcp-py/.venv/lib/python3.12/site-packages/httpcore/_async/connection.py\", line 78, in handle_async_request\n    |     stream = await self._connect(request)\n    |              ^^^^^^^^^^^^^^^^^^^^^^^^^^^^\n    |   File \"/home/user/funmula/dive-mcp-py/.venv/lib/python3.12/site-packages/httpcore/_async/connection.py\", line 124, in _connect\n    |     stream = await self._network_backend.connect_tcp(**kwargs)\n    |              ^^^^^^^^^^^^^^^^^^^^^^^^^^^^^^^^^^^^^^^^^^^^^^^^^\n    |   File \"/home/user/funmula/dive-mcp-py/.venv/lib/python3.12/site-packages/httpcore/_backends/auto.py\", line 31, in connect_tcp\n    |     return await self._backend.connect_tcp(\n    |            ^^^^^^^^^^^^^^^^^^^^^^^^^^^^^^^^\n    |   File \"/home/user/funmula/dive-mcp-py/.venv/lib/python3.12/site-packages/httpcore/_backends/anyio.py\", line 113, in connect_tcp\n    |     with map_exceptions(exc_map):\n    |          ^^^^^^^^^^^^^^^^^^^^^^^\n    |   File \"/home/user/.local/share/uv/python/cpython-3.12.9-linux-x86_64-gnu/lib/python3.12/contextlib.py\", line 158, in __exit__\n    |     self.gen.throw(value)\n    |   File \"/home/user/funmula/dive-mcp-py/.venv/lib/python3.12/site-packages/httpcore/_exceptions.py\", line 14, in map_exceptions\n    |     raise to_exc(exc) from exc\n    | httpcore.ConnectError: All connection attempts failed\n    | \n    | The above exception was the direct cause of the following exception:\n    | \n    | Traceback (most recent call last):\n    |   File \"/home/user/funmula/dive-mcp-py/.venv/lib/python3.12/site-packages/mcp/client/sse.py\", line 49, in sse_client\n    |     async with aconnect_sse(\n    |                ^^^^^^^^^^^^^\n    |   File \"/home/user/.local/share/uv/python/cpython-3.12.9-linux-x86_64-gnu/lib/python3.12/contextlib.py\", line 210, in __aenter__\n    |     return await anext(self.gen)\n    |            ^^^^^^^^^^^^^^^^^^^^^\n    |   File \"/home/user/funmula/dive-mcp-py/.venv/lib/python3.12/site-packages/httpx_sse/_api.py\", line 69, in aconnect_sse\n    |     async with client.stream(method, url, headers=headers, **kwargs) as response:\n    |                ^^^^^^^^^^^^^^^^^^^^^^^^^^^^^^^^^^^^^^^^^^^^^^^^^^^^^\n    |   File \"/home/user/.local/share/uv/python/cpython-3.12.9-linux-x86_64-gnu/lib/python3.12/contextlib.py\", line 210, in __aenter__\n    |     return await anext(self.gen)\n    |            ^^^^^^^^^^^^^^^^^^^^^\n    |   File \"/home/user/funmula/dive-mcp-py/.venv/lib/python3.12/site-packages/httpx/_client.py\", line 1583, in stream\n    |     response = await self.send(\n    |                ^^^^^^^^^^^^^^^^\n    |   File \"/home/user/funmula/dive-mcp-py/.venv/lib/python3.12/site-packages/httpx/_client.py\", line 1629, in send\n    |     response = await self._send_handling_auth(\n    |                ^^^^^^^^^^^^^^^^^^^^^^^^^^^^^^^\n    |   File \"/home/user/funmula/dive-mcp-py/.venv/lib/python3.12/site-packages/httpx/_client.py\", line 1657, in _send_handling_auth\n    |     response = await self._send_handling_redirects(\n    |                ^^^^^^^^^^^^^^^^^^^^^^^^^^^^^^^^^^^^\n    |   File \"/home/user/funmula/dive-mcp-py/.venv/lib/python3.12/site-packages/httpx/_client.py\", line 1694, in _send_handling_redirects\n    |     response = await self._send_single_request(request)\n    |                ^^^^^^^^^^^^^^^^^^^^^^^^^^^^^^^^^^^^^^^^\n    |   File \"/home/user/funmula/dive-mcp-py/.venv/lib/python3.12/site-packages/httpx/_client.py\", line 1730, in _send_single_request\n    |     response = await transport.handle_async_request(request)\n    |                ^^^^^^^^^^^^^^^^^^^^^^^^^^^^^^^^^^^^^^^^^^^^^\n    |   File \"/home/user/funmula/dive-mcp-py/.venv/lib/python3.12/site-packages/httpx/_transports/default.py\", line 393, in handle_async_request\n    |     with map_httpcore_exceptions():\n    |          ^^^^^^^^^^^^^^^^^^^^^^^^^\n    |   File \"/home/user/.local/share/uv/python/cpython-3.12.9-linux-x86_64-gnu/lib/python3.12/contextlib.py\", line 158, in __exit__\n    |     self.gen.throw(value)\n    |   File \"/home/user/funmula/dive-mcp-py/.venv/lib/python3.12/site-packages/httpx/_transports/default.py\", line 118, in map_httpcore_exceptions\n    |     raise mapped_exc(message) from exc\n    | httpx.ConnectError: All connection attempts failed\n    +------------------------------------\n","mcp_server_name":"echo","client_state":"init","timestamp":"2025-05-08T02:59:51.293363Z"}
{"event":"status_change","body":"client status changed, echo failed, error: False","mcp_server_name":"echo","client_state":"failed","timestamp":"2025-05-08T02:59:51.293751Z"}
{"event":"session_error","body":"  | dive_mcp_host.host.errors.McpSessionGroupError: Client initialization error for echo: (RemoteProtocolError('Server disconnected without sending a response.'),) (1 sub-exception)\n  +-+---------------- 1 ----------------\n    | Traceback (most recent call last):\n    |   File \"/home/user/funmula/dive-mcp-py/.venv/lib/python3.12/site-packages/httpx/_transports/default.py\", line 101, in map_httpcore_exceptions\n    |     yield\n    |   File \"/home/user/funmula/dive-mcp-py/.venv/lib/python3.12/site-packages/httpx/_transports/default.py\", line 394, in handle_async_request\n    |     resp = await self._pool.handle_async_request(req)\n    |            ^^^^^^^^^^^^^^^^^^^^^^^^^^^^^^^^^^^^^^^^^^\n    |   File \"/home/user/funmula/dive-mcp-py/.venv/lib/python3.12/site-packages/httpcore/_async/connection_pool.py\", line 256, in handle_async_request\n    |     raise exc from None\n    |   File \"/home/user/funmula/dive-mcp-py/.venv/lib/python3.12/site-packages/httpcore/_async/connection_pool.py\", line 236, in handle_async_request\n    |     response = await connection.handle_async_request(\n    |                ^^^^^^^^^^^^^^^^^^^^^^^^^^^^^^^^^^^^^^\n    |   File \"/home/user/funmula/dive-mcp-py/.venv/lib/python3.12/site-packages/httpcore/_async/connection.py\", line 103, in handle_async_request\n    |     return await self._connection.handle_async_request(request)\n    |            ^^^^^^^^^^^^^^^^^^^^^^^^^^^^^^^^^^^^^^^^^^^^^^^^^^^^\n    |   File \"/home/user/funmula/dive-mcp-py/.venv/lib/python3.12/site-packages/httpcore/_async/http11.py\", line 136, in handle_async_request\n    |     raise exc\n    |   File \"/home/user/funmula/dive-mcp-py/.venv/lib/python3.12/site-packages/httpcore/_async/http11.py\", line 106, in handle_async_request\n    |     ) = await self._receive_response_headers(**kwargs)\n    |         ^^^^^^^^^^^^^^^^^^^^^^^^^^^^^^^^^^^^^^^^^^^^^^\n    |   File \"/home/user/funmula/dive-mcp-py/.venv/lib/python3.12/site-packages/httpcore/_async/http11.py\", line 177, in _receive_response_headers\n    |     event = await self._receive_event(timeout=timeout)\n    |             ^^^^^^^^^^^^^^^^^^^^^^^^^^^^^^^^^^^^^^^^^^\n    |   File \"/home/user/funmula/dive-mcp-py/.venv/lib/python3.12/site-packages/httpcore/_async/http11.py\", line 231, in _receive_event\n    |     raise RemoteProtocolError(msg)\n    | httpcore.RemoteProtocolError: Server disconnected without sending a response.\n    | \n    | The above exception was the direct cause of the following exception:\n    | \n    | Traceback (most recent call last):\n    |   File \"/home/user/funmula/dive-mcp-py/.venv/lib/python3.12/site-packages/mcp/client/sse.py\", line 53, in sse_client\n    |     async with aconnect_sse(\n    |                ^^^^^^^^^^^^^\n    |   File \"/home/user/.local/share/uv/python/cpython-3.12.9-linux-x86_64-gnu/lib/python3.12/contextlib.py\", line 210, in __aenter__\n    |     return await anext(self.gen)\n    |            ^^^^^^^^^^^^^^^^^^^^^\n    |   File \"/home/user/funmula/dive-mcp-py/.venv/lib/python3.12/site-packages/httpx_sse/_api.py\", line 69, in aconnect_sse\n    |     async with client.stream(method, url, headers=headers, **kwargs) as response:\n    |                ^^^^^^^^^^^^^^^^^^^^^^^^^^^^^^^^^^^^^^^^^^^^^^^^^^^^^\n    |   File \"/home/user/.local/share/uv/python/cpython-3.12.9-linux-x86_64-gnu/lib/python3.12/contextlib.py\", line 210, in __aenter__\n    |     return await anext(self.gen)\n    |            ^^^^^^^^^^^^^^^^^^^^^\n    |   File \"/home/user/funmula/dive-mcp-py/.venv/lib/python3.12/site-packages/httpx/_client.py\", line 1583, in stream\n    |     response = await self.send(\n    |                ^^^^^^^^^^^^^^^^\n    |   File \"/home/user/funmula/dive-mcp-py/.venv/lib/python3.12/site-packages/httpx/_client.py\", line 1629, in send\n    |     response = await self._send_handling_auth(\n    |                ^^^^^^^^^^^^^^^^^^^^^^^^^^^^^^^\n    |   File \"/home/user/funmula/dive-mcp-py/.venv/lib/python3.12/site-packages/httpx/_client.py\", line 1657, in _send_handling_auth\n    |     response = await self._send_handling_redirects(\n    |                ^^^^^^^^^^^^^^^^^^^^^^^^^^^^^^^^^^^^\n    |   File \"/home/user/funmula/dive-mcp-py/.venv/lib/python3.12/site-packages/httpx/_client.py\", line 1694, in _send_handling_redirects\n    |     response = await self._send_single_request(request)\n    |                ^^^^^^^^^^^^^^^^^^^^^^^^^^^^^^^^^^^^^^^^\n    |   File \"/home/user/funmula/dive-mcp-py/.venv/lib/python3.12/site-packages/httpx/_client.py\", line 1730, in _send_single_request\n    |     response = await transport.handle_async_request(request)\n    |                ^^^^^^^^^^^^^^^^^^^^^^^^^^^^^^^^^^^^^^^^^^^^^\n    |   File \"/home/user/funmula/dive-mcp-py/.venv/lib/python3.12/site-packages/httpx/_transports/default.py\", line 393, in handle_async_request\n    |     with map_httpcore_exceptions():\n    |          ^^^^^^^^^^^^^^^^^^^^^^^^^\n    |   File \"/home/user/.local/share/uv/python/cpython-3.12.9-linux-x86_64-gnu/lib/python3.12/contextlib.py\", line 158, in __exit__\n    |     self.gen.throw(value)\n    |   File \"/home/user/funmula/dive-mcp-py/.venv/lib/python3.12/site-packages/httpx/_transports/default.py\", line 118, in map_httpcore_exceptions\n    |     raise mapped_exc(message) from exc\n    | httpx.RemoteProtocolError: Server disconnected without sending a response.\n    +------------------------------------\n","mcp_server_name":"echo","client_state":"init","timestamp":"2025-05-08T03:02:04.580141Z"}
{"event":"session_error","body":"  | dive_mcp_host.host.errors.McpSessionGroupError: Client initialization error for echo: (ConnectError('All connection attempts failed'),) (1 sub-exception)\n  +-+---------------- 1 ----------------\n    | Traceback (most recent call last):\n    |   File \"/home/user/funmula/dive-mcp-py/.venv/lib/python3.12/site-packages/httpx/_transports/default.py\", line 101, in map_httpcore_exceptions\n    |     yield\n    |   File \"/home/user/funmula/dive-mcp-py/.venv/lib/python3.12/site-packages/httpx/_transports/default.py\", line 394, in handle_async_request\n    |     resp = await self._pool.handle_async_request(req)\n    |            ^^^^^^^^^^^^^^^^^^^^^^^^^^^^^^^^^^^^^^^^^^\n    |   File \"/home/user/funmula/dive-mcp-py/.venv/lib/python3.12/site-packages/httpcore/_async/connection_pool.py\", line 256, in handle_async_request\n    |     raise exc from None\n    |   File \"/home/user/funmula/dive-mcp-py/.venv/lib/python3.12/site-packages/httpcore/_async/connection_pool.py\", line 236, in handle_async_request\n    |     response = await connection.handle_async_request(\n    |                ^^^^^^^^^^^^^^^^^^^^^^^^^^^^^^^^^^^^^^\n    |   File \"/home/user/funmula/dive-mcp-py/.venv/lib/python3.12/site-packages/httpcore/_async/connection.py\", line 101, in handle_async_request\n    |     raise exc\n    |   File \"/home/user/funmula/dive-mcp-py/.venv/lib/python3.12/site-packages/httpcore/_async/connection.py\", line 78, in handle_async_request\n    |     stream = await self._connect(request)\n    |              ^^^^^^^^^^^^^^^^^^^^^^^^^^^^\n    |   File \"/home/user/funmula/dive-mcp-py/.venv/lib/python3.12/site-packages/httpcore/_async/connection.py\", line 124, in _connect\n    |     stream = await self._network_backend.connect_tcp(**kwargs)\n    |              ^^^^^^^^^^^^^^^^^^^^^^^^^^^^^^^^^^^^^^^^^^^^^^^^^\n    |   File \"/home/user/funmula/dive-mcp-py/.venv/lib/python3.12/site-packages/httpcore/_backends/auto.py\", line 31, in connect_tcp\n    |     return await self._backend.connect_tcp(\n    |            ^^^^^^^^^^^^^^^^^^^^^^^^^^^^^^^^\n    |   File \"/home/user/funmula/dive-mcp-py/.venv/lib/python3.12/site-packages/httpcore/_backends/anyio.py\", line 113, in connect_tcp\n    |     with map_exceptions(exc_map):\n    |          ^^^^^^^^^^^^^^^^^^^^^^^\n    |   File \"/home/user/.local/share/uv/python/cpython-3.12.9-linux-x86_64-gnu/lib/python3.12/contextlib.py\", line 158, in __exit__\n    |     self.gen.throw(value)\n    |   File \"/home/user/funmula/dive-mcp-py/.venv/lib/python3.12/site-packages/httpcore/_exceptions.py\", line 14, in map_exceptions\n    |     raise to_exc(exc) from exc\n    | httpcore.ConnectError: All connection attempts failed\n    | \n    | The above exception was the direct cause of the following exception:\n    | \n    | Traceback (most recent call last):\n    |   File \"/home/user/funmula/dive-mcp-py/.venv/lib/python3.12/site-packages/mcp/client/sse.py\", line 48, in sse_client\n    |     async with aconnect_sse(\n    |                ^^^^^^^^^^^^^\n    |   File \"/home/user/.local/share/uv/python/cpython-3.12.9-linux-x86_64-gnu/lib/python3.12/contextlib.py\", line 210, in __aenter__\n    |     return await anext(self.gen)\n    |            ^^^^^^^^^^^^^^^^^^^^^\n    |   File \"/home/user/funmula/dive-mcp-py/.venv/lib/python3.12/site-packages/httpx_sse/_api.py\", line 69, in aconnect_sse\n    |     async with client.stream(method, url, headers=headers, **kwargs) as response:\n    |                ^^^^^^^^^^^^^^^^^^^^^^^^^^^^^^^^^^^^^^^^^^^^^^^^^^^^^\n    |   File \"/home/user/.local/share/uv/python/cpython-3.12.9-linux-x86_64-gnu/lib/python3.12/contextlib.py\", line 210, in __aenter__\n    |     return await anext(self.gen)\n    |            ^^^^^^^^^^^^^^^^^^^^^\n    |   File \"/home/user/funmula/dive-mcp-py/.venv/lib/python3.12/site-packages/httpx/_client.py\", line 1583, in stream\n    |     response = await self.send(\n    |                ^^^^^^^^^^^^^^^^\n    |   File \"/home/user/funmula/dive-mcp-py/.venv/lib/python3.12/site-packages/httpx/_client.py\", line 1629, in send\n    |     response = await self._send_handling_auth(\n    |                ^^^^^^^^^^^^^^^^^^^^^^^^^^^^^^^\n    |   File \"/home/user/funmula/dive-mcp-py/.venv/lib/python3.12/site-packages/httpx/_client.py\", line 1657, in _send_handling_auth\n    |     response = await self._send_handling_redirects(\n    |                ^^^^^^^^^^^^^^^^^^^^^^^^^^^^^^^^^^^^\n    |   File \"/home/user/funmula/dive-mcp-py/.venv/lib/python3.12/site-packages/httpx/_client.py\", line 1694, in _send_handling_redirects\n    |     response = await self._send_single_request(request)\n    |                ^^^^^^^^^^^^^^^^^^^^^^^^^^^^^^^^^^^^^^^^\n    |   File \"/home/user/funmula/dive-mcp-py/.venv/lib/python3.12/site-packages/httpx/_client.py\", line 1730, in _send_single_request\n    |     response = await transport.handle_async_request(request)\n    |                ^^^^^^^^^^^^^^^^^^^^^^^^^^^^^^^^^^^^^^^^^^^^^\n    |   File \"/home/user/funmula/dive-mcp-py/.venv/lib/python3.12/site-packages/httpx/_transports/default.py\", line 393, in handle_async_request\n    |     with map_httpcore_exceptions():\n    |          ^^^^^^^^^^^^^^^^^^^^^^^^^\n    |   File \"/home/user/.local/share/uv/python/cpython-3.12.9-linux-x86_64-gnu/lib/python3.12/contextlib.py\", line 158, in __exit__\n    |     self.gen.throw(value)\n    |   File \"/home/user/funmula/dive-mcp-py/.venv/lib/python3.12/site-packages/httpx/_transports/default.py\", line 118, in map_httpcore_exceptions\n    |     raise mapped_exc(message) from exc\n    | httpx.ConnectError: All connection attempts failed\n    +------------------------------------\n","mcp_server_name":"echo","client_state":"init","timestamp":"2025-05-08T03:24:51.944776Z"}
{"event":"status_change","body":"client status changed, echo failed, error: False","mcp_server_name":"echo","client_state":"failed","timestamp":"2025-05-08T03:24:51.945153Z"}
